Workbook

Sheet Summary
B2: Global temperature vs CO2, with natural-variability controls
B3: NASA GISTEMP v4 monthly anomalies × Mauna Loa CO2, Mar 1958 - Aug 2026, plus solar, ENSO, volcanic and full-forcing datasets. All numbers below are live links to the analysis tabs.
B5: Headline results
B6: Anthro-ERF regression scaled to F2x, °C per doubling (NOT TCR) | D6: Descriptive slope of T on log2(CO2), °C per doubling (NOT a response estimate) | F6: Detrended annual r (R² 0.40) | H6: Unexplained 2023-2025 residual (°C)
B7: =Forcing!T17 -> 1.6066886 | D7: =Annual!K4 -> 2.7423885 | F7: =Annual!K13 -> 0.63587131 | H7: =Volcanic!N39 -> 0.15129879
B8: ="Slope of annual T on anthropogenic ERF (ENSO controlled, 1959-2025) × F2x = 3.93 W/m². AR(1) 95% "&TEXT(Forcing!T20,"0.00")&" to "&TEXT(Forcing!U20,"0.00")&"; with F2x uncertainty "&TEXT(Forcing!T43,"0.00")&" to "&TEXT(Forcing!U43,"0.00")&"; with IGCC ERF uncertainty also propagated (Monte Carlo, Sensitivity!AC46) 1.43 to 1.78 at 90%. A historical-regression quantity, not the 1%/yr TCR experiment; numerical overlap with AR6 TCR is a comparison, not a validation." -> Slope of annual T on anthropogenic ERF (ENSO controlled, 1959-2025) × F2x = 3.93 W/m². AR(1) 95% 1.48 to 1.74; with F2x uncertainty 1.34 to 1.87; with IGCC ERF uncertainty also propagated (Monte Carlo, Sensitivity!AC46) 1.43 to 1.78 at 90%. A historical-regression quantity, not the 1%/yr TCR experiment; numerical overlap with AR6 TCR is a comparison, not a validation. | D8: ="Annual T on log2(CO2) alone, 67 years, R² 0.93; AR(1) 95% interval "&TEXT(Annual!K20,"0.00")&" to "&TEXT(Annual!L20,"0.00")&". Split sample: "&TEXT(Annual!K21,"0.00")&" (1959-91) vs "&TEXT(Annual!L21,"0.00")&" (1992-2025), a difference of only "&TEXT(Annual!K22,"0.0")&" adjusted SE. CO2 is collinear with total human forcing (r = 0.997), so this is NOT a CO2-only climate response." -> Annual T on log2(CO2) alone, 67 years, R² 0.93; AR(1) 95% interval 2.51 to 2.98. Split sample: 2.57 (1959-91) vs 3.19 (1992-2025), a difference of only 1.3 adjusted SE. CO2 is collinear with total human forcing (r = 0.997), so this is NOT a CO2-only climate response. | F8: Correlation of year-to-year wiggles after removing a linear time trend from both series. Shows the link is not only a shared trend; it does not remove ENSO or identify CO2 separately. | H8: ="Monthly: after CO2, ENSO and sulfate AOD. Annual, after full anthropogenic ERF (incl. aerosol change) + ENSO: "&TEXT(Forcing!T31,"+0.00")&"; with volcanic ERF incl. Hunga Tonga H2O as a regressor: "&TEXT(Forcing!T45,"+0.00")&". Persists under blocked cross-validation. Partly accounted for: see Recent 2023-25 tab (solar cycle 25 about half; ~0.07 °C remains, about one SE)." -> Monthly: after CO2, ENSO and sulfate AOD. Annual, after full anthropogenic ERF (incl. aerosol change) + ENSO: +0.14; with volcanic ERF incl. Hunga Tonga H2O as a regressor: +0.13. Persists under blocked cross-validation. Partly accounted for: see Recent 2023-25 tab (solar cycle 25 about half; ~0.07 °C remains, about one SE).
B10: How the fit improves as each control is added (monthly data)
B11: Model | C11: Months | D11: CO2, °C per doubling | E11: R² | F11: R² of previous model, same months | G11: Residual σ (°C) | H11: Lag-1 autocorr. (monthly) | I11: Added control coefficient | J11: Lag recovered | K11: Tab | M11: Model | N11: R² | O11: Residual σ
B12: CO2 only | C12: =Analysis!I7 -> 822 | D12: =Analysis!I11 -> 2.7335713 | E12: =Analysis!I12 -> 0.86092237 | G12: =ENSO!N7 -> 0.14507445 | H12: =ENSO!N8 -> 0.64377333 | K12: Analysis | M12: CO2 only | N12: =E12 -> 0.86092237 | O12: =G12 -> 0.14507445
B13: + ENSO (ONI, lag 3 mo) | C13: =ENSO!N18 -> 815 | D13: =ENSO!N15 -> 2.7467961 | E13: =ENSO!N17 -> 0.89162717 | F13: =ENSO!N22 -> 0.86058036 | G13: =ENSO!N19 -> 0.12801797 | H13: =ENSO!N20 -> 0.54654178 | I13: =ENSO!N16 -> 0.08703777 | J13: 3 months | K13: ENSO | M13: + ENSO | N13: =E13 -> 0.89162717 | O13: =G13 -> 0.12801797
B14: + volcanic AOD (lag 7 mo) | C14: =Volcanic!N19 -> 814 | D14: =Volcanic!N15 -> 2.7274259 | E14: =Volcanic!N18 -> 0.90076359 | F14: =Volcanic!N22 -> 0.89120225 | G14: =Volcanic!N20 -> 0.12208488 | H14: =Volcanic!N21 -> 0.50280224 | I14: =Volcanic!N17 -> -2.2003523 | J14: 6-8 months | K14: Volcanic | M14: + volcanic | N14: =E14 -> 0.90076359 | O14: =G14 -> 0.12208488
B15: + solar TSI (through 2023) | C15: =COUNT(Volcanic!F9:F791) -> 783 | D15: =Volcanic!N25 -> 2.6436323 | E15: =Volcanic!N29 -> 0.8932405 | F15: =Volcanic!N30 -> 0.88957834 | I15: =Volcanic!N28 -> 0.052957801 | J15: ~11-yr cycle | K15: Solar / Volcanic | M15: kernels | N15: =E16 -> 0.90365216 | O15: =G16 -> 0.11857711
B16: Exponential responses instead of single lags (CO2+ENSO+AOD) | C16: =Kernel!P18 -> 807 | D16: =Kernel!P14 -> 2.704174 | E16: =Kernel!P22 -> 0.90365216 | F16: =Kernel!P21 -> 0.89830013 | G16: =Kernel!P19 -> 0.11857711 | H16: =Kernel!P20 -> 0.47349 | J16: τ: ENSO 6 mo, AOD 12 mo | K16: Kernel
B17: Read each row against the "same months" column, not the row above. The CO2 column is NOT on matched months: the solar row's 2.64 is a window effect (CO2-only on the same 783 months is already 2.640, Volcanic!N31; see Analysis!H18 for end-point sensitivity). Coefficient units: ONI in °C of Niño 3.4 anomaly; AOD unitless (Pinatubo peak ≈ 0.11); TSI in W/m².
B19: What each control found
B20: Solar (TSI) | C20: No trend since 1958 in the TSI record used, and R² ≈ 0.00 on its own, so the Sun cannot be the warming trend in that record (confirmed with NOAA Solar CDR v3 on the Sensitivity tab). But an 11-year cycle consistent with the published ~0.1 °C swing appears in the residuals at ~0.07 °C per W/m² of TSI (~0.40 per W/m² of forcing). Adding TSI moves the CO2 slope from 2.640 to 2.644 on the same months; the apparent drop to 2.64 from 2.73 is the shorter window, not the Sun.
B21: ENSO (ONI) | C21: The dominant short-term noise. Best lag 3 months, ~0.09 °C per unit ONI, both consistent with textbook values (the lag was selected on this record, so this is consistency, not independent recovery). The ONI series used has essentially zero linear trend over the sample (its 30-year base periods are re-centred), so it absorbs none of the CO2 trend here and the CO2 coefficient does not materially move. ONI is not a complete ENSO control (RONI and ERSSTv6 exist; see data note).
B22: Volcanic (AOD) | C22: Best lag 6-8 months; implied peak cooling Pinatubo -0.25, Agung -0.18, El Chichón -0.13 °C. Transient response to a pulse (~0.13 °C per W/m²) is far below the sustained-forcing response (~0.40), which is why summing forcings of different duration and regressing makes the fit worse.
B23: Response kernels | C23: Replacing single lags with one-box exponential responses (τ ≈ 6 months for ENSO, 12 for volcanic AOD) improves the fit on identical months (R² 0.898 → 0.904) and leaves the CO2 coefficient at 2.70. τ was chosen on the full record; under blocked 7-fold cross-validation with τ and coefficients chosen out-of-fold, the same τ values are selected in nearly every fold and the pooled out-of-fold R² is 0.887 (CO2-only 0.838), so the specification is not an in-sample artefact, though the ΔR² is modestly optimistic. Filtering CO2 the same way has no R² optimum: the record cannot separate transient from equilibrium response.
B24: Full forcing (ERF) | C24: Anthropogenic ERF gives 0.40 °C per W/m², 1.6 °C per doubling when scaled by F2x (not TCR), inside the IPCC range. log2(CO2) and anthropogenic ERF are almost perfectly collinear (r = 0.997), so either fits equally well; this does NOT mean CO2 is a constant share of human forcing (its share falls from ~2.3× to ~0.75× of net anthropogenic ERF as aerosol offset shrinks), and the regression does not separate the components. Splitting human forcing into a warming term and an aerosol term gives the same response to each: 0.409 against 0.414 °C per W/m², a difference of -0.005 (Forcing!T21:T22). CORRECTED in v1.6: before that revision this split omitted the other anthropogenic column and reported 0.47 against 0.37, which was an omitted-variable artefact. The two series are nearly orthogonal over this record, so the regression does separate them, but because aerosol ERF is the widest uncertainty in AR6 the data fix the aerosol contribution rather than the response per W/m². See Open Items section B. Giving volcanic ERF its own coefficient gives R² 0.96 and leaves the F2x-scaled (not TCR) value at ~1.59. Aerosol ERF changes ~0.15 W/m² 2019-25 in this dataset, worth ~0.06 °C, so it explains part but not most of the 2023-25 excess.
B26: What this analysis does and does not show
B27: Does: over 1959-2025, log2(CO2) and anthropogenic ERF are interchangeable regressors (r = 0.997). GISTEMP regressed on that proxy plus ONI has in-sample R² ≈ 0.89 monthly and ≈ 0.95 annual; both are dominated by the shared trend, and after linear detrending the annual r is 0.64 (R² 0.40). On matched months, adding ONI, AOD or TSI leaves the CO2 slope within ~0.02 of its CO2-only value. Blocked cross-validation with lag structure and coefficients chosen out-of-fold gives pooled R² 0.887 (Kernel!P62:Q70). Scaling the anthropogenic-ERF slope by F2x gives 1.61 °C per doubling (95% 1.34 to 1.87 with F2x uncertainty; 1.43 to 1.78 at 90% with IGCC ERF uncertainty propagated, Sensitivity!AC46), which is numerically inside the AR6 TCR likely range; that is a comparison, not a validation, since it is not the TCR estimand.
B28: Does not: estimate equilibrium climate sensitivity (a 66-year single-realisation record cannot), and "scaled to F2x" means an observational regression estimate, not the formal 1%-per-year model experiment; establish causation by itself (that rests on radiative physics and fingerprints such as stratospheric cooling); or fully explain the 2023-25 excess warmth: the Recent 2023-25 tab accounts for roughly half of the annual-model residual with solar cycle 25, and the remainder (~0.07 °C) is about one standard error of a 3-year mean. Read that last comparison with the qualifier added in v1.7 at Recent 2023-25!B30:B32: the asymptotic AR(1) formula gives 0.067 for that standard error, the exact AR(1) variance of a mean of three gives 0.058, so the remainder is about 1.2 SE, and the residual BEFORE the solar line is about 2.2 SE. The budget is exploratory and the solar line carries its own unstated uncertainty.
B29: Statistics: all fits are ordinary least squares with autocorrelated residuals (lag-1 ≈ 0.5 monthly, ≈ 0.3 annual; effective n ≈ 40 annual). The monthly effective n of ≈ 290 quoted here before v1.7 came from the AR(1) factor and overstates the independent information: Newey-West out to 96 lags implies a variance inflation near 14, i.e. an effective n nearer 60 monthly (Diagnostics section D item 5). Nothing published rests on the monthly slope. AR(1)-inflated standard errors and 95% intervals are given for the two headline slopes (Annual!K17:L20, Forcing!T19:U20). Lag and τ values were chosen in-sample; Kernel!P51:P60 is only a coefficient holdout with τ fixed. The nested check is Kernel!P62:Q70: a single 1958-95 split cannot identify τ (long τ, degraded holdout), but blocked 7-fold cross-validation selects the same τ values out-of-fold and gives pooled R² 0.887 vs 0.904 in-sample. Newey-West SEs (1-6 lags) on the annual slope, 0.120-0.126, confirm the AR(1) correction.
B30: Data vintages (Sept 2026 review): ERF from the IGCC 2025 file (1750-2025), with its 5-95% percentile files used for uncertainty propagation. Main analysis uses NOAA CPC ONI on ERSSTv5, ClimateIndicator sulfate AOD (GloSSAC v2.23 basis) and NRLTSI2. The successors (ONI on ERSSTv6, GloSSAC v2.24, NOAA Solar CDR v3) were rerun on the Sensitivity tab; no result changes materially. Monthly AOD is sulfate only; Hunga Tonga stratospheric water vapour appears only in the annual volcanic ERF on the Forcing tab and in the Recent 2023-25 budget. HadCRUT5 and Berkeley Earth were run in place of GISTEMP (Sensitivity tab); the headline slopes change by at most 0.05 and the 2023-25 residual by 0.02-0.03 °C.
B31: Sources: NASA GISTEMP v4; NOAA GML Mauna Loa CO2; NRLTSI2 (LASP LISIRD); NOAA CPC ONI; ClimateIndicator/forcing-timeseries (Forster et al.) for volcanic AOD and all ERF series. Download dates and provenance are in the header-cell comments on each tab.
B33: Out-of-sample validation and residual diagnostics (added 2026-10-22)
B34: The two tables above are in-sample. The blocked cross-validation on the Kernel tab and the specification tests on the Diagnostics tab are the out-of-sample and residual checks.
B36: Out-of-sample fit: blocked 7-fold cross-validation, tau and coefficients chosen out-of-fold
B37: Model | C37: In-sample R^2 | D37: Out-of-fold R^2 | E37: Bias (degC) | F37: Source
B38: CO2 only (monthly) | C38: =E12 -> 0.86092237 | D38: =Kernel!P69 -> 0.838 | F38: Kernel!P69
B39: CO2 + ENSO + AOD, exponential responses | C39: =E16 -> 0.90365216 | D39: =Kernel!P66 -> 0.887 | E39: =Kernel!Q66 -> 0.003 | F39: Kernel!P66:Q66
B40: Same, tau fixed at (6, 12) | C40: =E16 -> 0.90365216 | D40: =Kernel!P68 -> 0.889 | E40: =Kernel!Q68 -> 0.003 | F40: Kernel!P68:Q68
B41: Judge the gain from the natural-variability controls on the out-of-fold column, 0.838 to 0.887, rather than on the in-sample 0.861 to 0.904 above. Bias is the mean out-of-fold prediction error in degC. Read the pooled figures with one caveat added in v1.6: pooled out-of-fold R^2 is dominated by the cross-decade trend, which a monotone CO2-only regressor extrapolates across blocks, so the CO2-only benchmark flatters itself. Within each fold the CO2-only R^2 is near zero or negative while the three-factor model cuts the RMSE in every fold; validate_kernels.py now prints both.
B43: Heteroskedasticity and variance clustering (Diagnostics tab)
B44: Breusch-Pagan and White on the monthly three-factor residuals are marginal to significant (p about 0.03 and 0.004) but the auxiliary regressions explain only 1 to 3 per cent of the squared residuals. The large ARCH statistics turn out to be an artefact of the level autocorrelation already documented here: after filtering it out, ARCH-LM at q = 1 falls from about 42 to under 1 (p about 0.4) and Breusch-Pagan is far from significant. On the two annual models almost nothing is detected (Breusch-Pagan p = 0.28 and 0.40), the one marginal statistic being White on the CO2-proxy model at p = 0.035 on 67 points. The corrections are not interchangeable: HC3, robust to heteroskedasticity alone, raises the slope standard errors by 18 per cent (annual CO2 proxy), 4 per cent (annual ERF) and 9 per cent (monthly); the AR(1) inflation addresses serial correlation only; Newey-West covers both. On both annual slopes the AR(1)-inflated standard errors published here are the widest or within a per cent of the widest of the four measures, so no published interval changes. The monthly slope, on which no interval is published, is the one place the AR(1) factor is not the conservative choice.
B45: Detail and live formulas: Diagnostics!AW5:BB51. Standard errors for all three slopes, naive against HC3, Newey-West and AR(1)-inflated: Diagnostics!AX31:BA33. The three questions the reviews left open, RONI as the ENSO control, whether the GHG-aerosol split is identified, and the CERES shortwave candidate for the 2023-25 remainder, are worked through on the Open Items tab.
B47: Workbook version
B48: Version | C48: 1.7.11 | D48: v1.0 = the Sept 2026 state; v1.1 to v1.7.4 were all issued 2026-10-22; v1.7.5 and v1.7.6 on 2026-10-23.
B49: Date of this revision | C49: 2026-10-23
...

Sheet Analysis
A1: Month/Year | B1: Year (decimal) | C1: Temp (°F) | D1: CO2 (ppm) | E1: Anomaly (°C vs 1951-80) | F1: log2(CO2/preindustrial)
A2: ='F Plus CO2'!A940 -> 3/1958 | B2: =VALUE(RIGHT(A2,4))+(VALUE(LEFT(A2,FIND("/",A2)-1))-0.5)/12 -> 1958.2083 | C2: ='F Plus CO2'!B940 -> 57.344 | D2: ='F Plus CO2'!C940 -> 315.71 | E2: =(C2-32)*5/9-$I$3 -> 0.08 | F2: =LOG(D2/$I$4,2) -> 0.17317313 | H2: Assumptions (edit yellow cells)
A3: ='F Plus CO2'!A941 -> 4/1958 | B3: =VALUE(RIGHT(A3,4))+(VALUE(LEFT(A3,FIND("/",A3)-1))-0.5)/12 -> 1958.2917 | C3: ='F Plus CO2'!B941 -> 57.218 | D3: ='F Plus CO2'!C941 -> 317.45 | E3: =(C3-32)*5/9-$I$3 -> 0.01 | F3: =LOG(D3/$I$4,2) -> 0.18110255 | H3: GISTEMP absolute baseline (°C) | I3: 14
A4: ='F Plus CO2'!A942 -> 5/1958 | B4: =VALUE(RIGHT(A4,4))+(VALUE(LEFT(A4,FIND("/",A4)-1))-0.5)/12 -> 1958.375 | C4: ='F Plus CO2'!B942 -> 57.308 | D4: ='F Plus CO2'!C942 -> 317.51 | E4: =(C4-32)*5/9-$I$3 -> 0.06 | F4: =LOG(D4/$I$4,2) -> 0.1813752 | H4: Preindustrial CO2 (ppm) | I4: 280
A5: ='F Plus CO2'!A943 -> 6/1958 | B5: =VALUE(RIGHT(A5,4))+(VALUE(LEFT(A5,FIND("/",A5)-1))-0.5)/12 -> 1958.4583 | C5: ='F Plus CO2'!B943 -> 57.038 | D5: ='F Plus CO2'!C943 -> 317.27 | E5: =(C5-32)*5/9-$I$3 -> -0.09 | F5: =LOG(D5/$I$4,2) -> 0.18028428
A6: ='F Plus CO2'!A944 -> 7/1958 | B6: =VALUE(RIGHT(A6,4))+(VALUE(LEFT(A6,FIND("/",A6)-1))-0.5)/12 -> 1958.5417 | C6: ='F Plus CO2'!B944 -> 57.29 | D6: ='F Plus CO2'!C944 -> 315.87 | E6: =(C6-32)*5/9-$I$3 -> 0.05 | F6: =LOG(D6/$I$4,2) -> 0.1739041 | H6: Fit statistics (all monthly pairs)
A7: ='F Plus CO2'!A945 -> 8/1958 | B7: =VALUE(RIGHT(A7,4))+(VALUE(LEFT(A7,FIND("/",A7)-1))-0.5)/12 -> 1958.625 | C7: ='F Plus CO2'!B945 -> 57.11 | D7: ='F Plus CO2'!C945 -> 314.93 | E7: =(C7-32)*5/9-$I$3 -> -0.05 | F7: =LOG(D7/$I$4,2) -> 0.16960437 | H7: Months in fit | I7: =COUNT($E$2:$E$823) -> 822
A8: ='F Plus CO2'!A946 -> 9/1958 | B8: =VALUE(RIGHT(A8,4))+(VALUE(LEFT(A8,FIND("/",A8)-1))-0.5)/12 -> 1958.7083 | C8: ='F Plus CO2'!B946 -> 57.146 | D8: ='F Plus CO2'!C946 -> 313.21 | E8: =(C8-32)*5/9-$I$3 -> -0.03 | F8: =LOG(D8/$I$4,2) -> 0.16170345 | H8: Slope, °C per 100 ppm | I8: =SLOPE($E$2:$E$823,$D$2:$D$823)*100 -> 1.0819022
A9: ='F Plus CO2'!A947 -> 10/1958 | B9: =VALUE(RIGHT(A9,4))+(VALUE(LEFT(A9,FIND("/",A9)-1))-0.5)/12 -> 1958.7917 | C9: ='F Plus CO2'!B947 -> 57.272 | D9: ='F Plus CO2'!C947 -> 312.42 | E9: =(C9-32)*5/9-$I$3 -> 0.04 | F9: =LOG(D9/$I$4,2) -> 0.15805999 | H9: Intercept (°C at 0 ppm) | I9: =INTERCEPT($E$2:$E$823,$D$2:$D$823) -> -3.5067569
A10: ='F Plus CO2'!A948 -> 11/1958 | B10: =VALUE(RIGHT(A10,4))+(VALUE(LEFT(A10,FIND("/",A10)-1))-0.5)/12 -> 1958.875 | C10: ='F Plus CO2'!B948 -> 57.236 | D10: ='F Plus CO2'!C948 -> 313.33 | E10: =(C10-32)*5/9-$I$3 -> 0.02 | F10: =LOG(D10/$I$4,2) -> 0.16225608 | H10: R², anomaly vs CO2 | I10: =RSQ($E$2:$E$823,$D$2:$D$823) -> 0.86577375
A11: ='F Plus CO2'!A949 -> 12/1958 | B11: =VALUE(RIGHT(A11,4))+(VALUE(LEFT(A11,FIND("/",A11)-1))-0.5)/12 -> 1958.9583 | C11: ='F Plus CO2'!B949 -> 57.218 | D11: ='F Plus CO2'!C949 -> 314.67 | E11: =(C11-32)*5/9-$I$3 -> 0.01 | F11: =LOG(D11/$I$4,2) -> 0.16841281 | H11: Slope, °C per doubling of CO2 | I11: =SLOPE($E$2:$E$823,$F$2:$F$823) -> 2.7335713
A12: ='F Plus CO2'!A950 -> 1/1959 | B12: =VALUE(RIGHT(A12,4))+(VALUE(LEFT(A12,FIND("/",A12)-1))-0.5)/12 -> 1959.0417 | C12: ='F Plus CO2'!B950 -> 57.344 | D12: ='F Plus CO2'!C950 -> 315.58 | E12: =(C12-32)*5/9-$I$3 -> 0.08 | F12: =LOG(D12/$I$4,2) -> 0.17257895 | H12: R², anomaly vs log2(CO2) | I12: =RSQ($E$2:$E$823,$F$2:$F$823) -> 0.86092237
A13: ='F Plus CO2'!A951 -> 2/1959 | B13: =VALUE(RIGHT(A13,4))+(VALUE(LEFT(A13,FIND("/",A13)-1))-0.5)/12 -> 1959.125 | C13: ='F Plus CO2'!B951 -> 57.326 | D13: ='F Plus CO2'!C951 -> 316.49 | E13: =(C13-32)*5/9-$I$3 -> 0.07 | F13: =LOG(D13/$I$4,2) -> 0.17673309 | H13: Correlation r | I13: =CORREL($E$2:$E$823,$D$2:$D$823) -> 0.93046964
A14: ='F Plus CO2'!A952 -> 3/1959 | B14: =VALUE(RIGHT(A14,4))+(VALUE(LEFT(A14,FIND("/",A14)-1))-0.5)/12 -> 1959.2083 | C14: ='F Plus CO2'!B952 -> 57.524 | D14: ='F Plus CO2'!C952 -> 316.65 | E14: =(C14-32)*5/9-$I$3 -> 0.18 | F14: =LOG(D14/$I$4,2) -> 0.17746225
A15: ='F Plus CO2'!A953 -> 4/1959 | B15: =VALUE(RIGHT(A15,4))+(VALUE(LEFT(A15,FIND("/",A15)-1))-0.5)/12 -> 1959.2917 | C15: ='F Plus CO2'!B953 -> 57.488 | D15: ='F Plus CO2'!C953 -> 317.72 | E15: =(C15-32)*5/9-$I$3 -> 0.16 | F15: =LOG(D15/$I$4,2) -> 0.18232908 | H15: Note: residuals are strongly autocorrelated (monthly ENSO/volcanic noise), so naive standard errors on these slopes would be too small. Slopes and R² are descriptive.
A16: ='F Plus CO2'!A954 -> 5/1959 | B16: =VALUE(RIGHT(A16,4))+(VALUE(LEFT(A16,FIND("/",A16)-1))-0.5)/12 -> 1959.375 | C16: ='F Plus CO2'!B954 -> 57.272 | D16: ='F Plus CO2'!C954 -> 318.29 | E16: =(C16-32)*5/9-$I$3 -> 0.04 | F16: =LOG(D16/$I$4,2) -> 0.184915 | H16: Sources: NASA GISTEMP v4 land+ocean monthly anomalies (tab GLB.Ts+dSST (4), via Temp Dev, C, F); NOAA GML Mauna Loa monthly mean CO2 (tab co2_mm_mlo, via F Plus CO2). Full provenance on the Sources tab and in DATA_SOURCES.md.
A17: ='F Plus CO2'!A955 -> 6/1959 | B17: =VALUE(RIGHT(A17,4))+(VALUE(LEFT(A17,FIND("/",A17)-1))-0.5)/12 -> 1959.4583 | C17: ='F Plus CO2'!B955 -> 57.254 | D17: ='F Plus CO2'!C955 -> 318.15 | E17: =(C17-32)*5/9-$I$3 -> 0.03 | F17: =LOG(D17/$I$4,2) -> 0.18428029
A18: ='F Plus CO2'!A956 -> 7/1959 | B18: =VALUE(RIGHT(A18,4))+(VALUE(LEFT(A18,FIND("/",A18)-1))-0.5)/12 -> 1959.5417 | C18: ='F Plus CO2'!B956 -> 57.254 | D18: ='F Plus CO2'!C956 -> 316.54 | E18: =(C18-32)*5/9-$I$3 -> 0.03 | F18: =LOG(D18/$I$4,2) -> 0.17696099 | H18: End-point sensitivity: monthly CO2-only slope (°C per doubling) by last month included
A19: ='F Plus CO2'!A957 -> 8/1959 | B19: =VALUE(RIGHT(A19,4))+(VALUE(LEFT(A19,FIND("/",A19)-1))-0.5)/12 -> 1959.625 | C19: ='F Plus CO2'!B957 -> 57.182 | D19: ='F Plus CO2'!C957 -> 314.8 | E19: =(C19-32)*5/9-$I$3 -> -0.01 | F19: =LOG(D19/$I$4,2) -> 0.16900871 | H19: through Dec 2022 | I19: =SLOPE($E$2:$E$779,$F$2:$F$779) -> 2.5849313
A20: ='F Plus CO2'!A958 -> 9/1959 | B20: =VALUE(RIGHT(A20,4))+(VALUE(LEFT(A20,FIND("/",A20)-1))-0.5)/12 -> 1959.7083 | C20: ='F Plus CO2'!B958 -> 57.092 | D20: ='F Plus CO2'!C958 -> 313.84 | E20: =(C20-32)*5/9-$I$3 -> -0.06 | F20: =LOG(D20/$I$4,2) -> 0.16460241 | H20: through Dec 2023 | I20: =SLOPE($E$2:$E$791,$F$2:$F$791) -> 2.62928
A21: ='F Plus CO2'!A959 -> 10/1959 | B21: =VALUE(RIGHT(A21,4))+(VALUE(LEFT(A21,FIND("/",A21)-1))-0.5)/12 -> 1959.7917 | C21: ='F Plus CO2'!B959 -> 57.074 | D21: ='F Plus CO2'!C959 -> 313.33 | E21: =(C21-32)*5/9-$I$3 -> -0.07 | F21: =LOG(D21/$I$4,2) -> 0.16225608 | H21: through Dec 2024 | I21: =SLOPE($E$2:$E$803,$F$2:$F$803) -> 2.6884783
A22: ='F Plus CO2'!A960 -> 11/1959 | B22: =VALUE(RIGHT(A22,4))+(VALUE(LEFT(A22,FIND("/",A22)-1))-0.5)/12 -> 1959.875 | C22: ='F Plus CO2'!B960 -> 57.056 | D22: ='F Plus CO2'!C960 -> 314.81 | E22: =(C22-32)*5/9-$I$3 -> -0.08 | F22: =LOG(D22/$I$4,2) -> 0.16905454 | H22: through Dec 2025 | I22: =SLOPE($E$2:$E$815,$F$2:$F$815) -> 2.7158666
A23: ='F Plus CO2'!A961 -> 12/1959 | B23: =VALUE(RIGHT(A23,4))+(VALUE(LEFT(A23,FIND("/",A23)-1))-0.5)/12 -> 1959.9583 | C23: ='F Plus CO2'!B961 -> 57.2 | D23: ='F Plus CO2'!C961 -> 315.58 | E23: =(C23-32)*5/9-$I$3 -> 0 | F23: =LOG(D23/$I$4,2) -> 0.17257895 | H23: through Aug 2026 (all) | I23: =SLOPE($E$2:$E$823,$F$2:$F$823) -> 2.7335713
A24: ='F Plus CO2'!A962 -> 1/1960 | B24: =VALUE(RIGHT(A24,4))+(VALUE(LEFT(A24,FIND("/",A24)-1))-0.5)/12 -> 1960.0417 | C24: ='F Plus CO2'!B962 -> 57.2 | D24: ='F Plus CO2'!C962 -> 316.43 | E24: =(C24-32)*5/9-$I$3 -> 0 | F24: =LOG(D24/$I$4,2) -> 0.17645956 | H24: The last three years lever the slope by ~0.15 °C per doubling. Any coefficient comparison must be made on identical months.
A25: ='F Plus CO2'!A963 -> 2/1960 | B25: =VALUE(RIGHT(A25,4))+(VALUE(LEFT(A25,FIND("/",A25)-1))-0.5)/12 -> 1960.125 | C25: ='F Plus CO2'!B963 -> 57.434 | D25: ='F Plus CO2'!C963 -> 316.98 | E25: =(C25-32)*5/9-$I$3 -> 0.13 | F25: =LOG(D25/$I$4,2) -> 0.17896499
A26: ='F Plus CO2'!A964 -> 3/1960 | B26: =VALUE(RIGHT(A26,4))+(VALUE(LEFT(A26,FIND("/",A26)-1))-0.5)/12 -> 1960.2083 | C26: ='F Plus CO2'!B964 -> 56.57 | D26: ='F Plus CO2'!C964 -> 317.58 | E26: =(C26-32)*5/9-$I$3 -> -0.35 | F26: =LOG(D26/$I$4,2) -> 0.18169323
A27: ='F Plus CO2'!A965 -> 4/1960 | B27: =VALUE(RIGHT(A27,4))+(VALUE(LEFT(A27,FIND("/",A27)-1))-0.5)/12 -> 1960.2917 | C27: ='F Plus CO2'!B965 -> 56.93 | D27: ='F Plus CO2'!C965 -> 319.03 | E27: =(C27-32)*5/9-$I$3 -> -0.15 | F27: =LOG(D27/$I$4,2) -> 0.18826527
A28: ='F Plus CO2'!A966 -> 5/1960 | B28: =VALUE(RIGHT(A28,4))+(VALUE(LEFT(A28,FIND("/",A28)-1))-0.5)/12 -> 1960.375 | C28: ='F Plus CO2'!B966 -> 57.056 | D28: ='F Plus CO2'!C966 -> 320.03 | E28: =(C28-32)*5/9-$I$3 -> -0.08 | F28: =LOG(D28/$I$4,2) -> 0.19278032
A29: ='F Plus CO2'!A967 -> 6/1960 | B29: =VALUE(RIGHT(A29,4))+(VALUE(LEFT(A29,FIND("/",A29)-1))-0.5)/12 -> 1960.4583 | C29: ='F Plus CO2'!B967 -> 57.128 | D29: ='F Plus CO2'!C967 -> 319.58 | E29: =(C29-32)*5/9-$I$3 -> -0.04 | F29: =LOG(D29/$I$4,2) -> 0.1907503
A30: ='F Plus CO2'!A968 -> 7/1960 | B30: =VALUE(RIGHT(A30,4))+(VALUE(LEFT(A30,FIND("/",A30)-1))-0.5)/12 -> 1960.5417 | C30: ='F Plus CO2'!B968 -> 57.128 | D30: ='F Plus CO2'!C968 -> 318.18 | E30: =(C30-32)*5/9-$I$3 -> -0.04 | F30: =LOG(D30/$I$4,2) -> 0.18441633
A31: ='F Plus CO2'!A969 -> 8/1960 | B31: =VALUE(RIGHT(A31,4))+(VALUE(LEFT(A31,FIND("/",A31)-1))-0.5)/12 -> 1960.625 | C31: ='F Plus CO2'!B969 -> 57.236 | D31: ='F Plus CO2'!C969 -> 315.9 | E31: =(C31-32)*5/9-$I$3 -> 0.02 | F31: =LOG(D31/$I$4,2) -> 0.17404111
A32: ='F Plus CO2'!A970 -> 9/1960 | B32: =VALUE(RIGHT(A32,4))+(VALUE(LEFT(A32,FIND("/",A32)-1))-0.5)/12 -> 1960.7083 | C32: ='F Plus CO2'!B970 -> 57.326 | D32: ='F Plus CO2'!C970 -> 314.17 | E32: =(C32-32)*5/9-$I$3 -> 0.07 | F32: =LOG(D32/$I$4,2) -> 0.1661186
A33: ='F Plus CO2'!A971 -> 10/1960 | B33: =VALUE(RIGHT(A33,4))+(VALUE(LEFT(A33,FIND("/",A33)-1))-0.5)/12 -> 1960.7917 | C33: ='F Plus CO2'!B971 -> 57.308 | D33: ='F Plus CO2'!C971 -> 313.83 | E33: =(C33-32)*5/9-$I$3 -> 0.06 | F33: =LOG(D33/$I$4,2) -> 0.16455644
A34: ='F Plus CO2'!A972 -> 11/1960 | B34: =VALUE(RIGHT(A34,4))+(VALUE(LEFT(A34,FIND("/",A34)-1))-0.5)/12 -> 1960.875 | C34: ='F Plus CO2'!B972 -> 57.002 | D34: ='F Plus CO2'!C972 -> 315 | E34: =(C34-32)*5/9-$I$3 -> -0.11 | F34: =LOG(D34/$I$4,2) -> 0.169925
A35: ='F Plus CO2'!A973 -> 12/1960 | B35: =VALUE(RIGHT(A35,4))+(VALUE(LEFT(A35,FIND("/",A35)-1))-0.5)/12 -> 1960.9583 | C35: ='F Plus CO2'!B973 -> 57.542 | D35: ='F Plus CO2'!C973 -> 316.19 | E35: =(C35-32)*5/9-$I$3 -> 0.19 | F35: =LOG(D35/$I$4,2) -> 0.17536491
A36: ='F Plus CO2'!A974 -> 1/1961 | B36: =VALUE(RIGHT(A36,4))+(VALUE(LEFT(A36,FIND("/",A36)-1))-0.5)/12 -> 1961.0417 | C36: ='F Plus CO2'!B974 -> 57.326 | D36: ='F Plus CO2'!C974 -> 316.89 | E36: =(C36-32)*5/9-$I$3 -> 0.07 | F36: =LOG(D36/$I$4,2) -> 0.17855531
... A823: ='F Plus CO2'!A1761 -> 8/2026 | B823: =VALUE(RIGHT(A823,4))+(VALUE(LEFT(A823,FIND("/",A823)-1))-0.5)/12 -> 2026.625 | C823: ='F Plus CO2'!B1761 -> 59.72 | D823: ='F Plus CO2'!C1761 -> 427.55 | E823: =(C823-32)*5/9-$I$3 -> 1.4 | F823: =LOG(D823/$I$4,2) -> 0.61066632

Sheet Annual
A1: Year | B1: Months | C1: Mean CO2 (ppm) | D1: Mean anomaly (°C) | E1: Mean log2(CO2/280) | F1: Anomaly, linear time trend removed | G1: log2 CO2, linear time trend removed | H1: Fit residual (anomaly - log fit)
A2: 1959 | B2: =COUNTIFS(Analysis!$B$2:$B$823,">="&A2,Analysis!$B$2:$B$823,"<"&(A2+1)) -> 12 | C2: =AVERAGEIFS(Analysis!$D$2:$D$823,Analysis!$B$2:$B$823,">="&A2,Analysis!$B$2:$B$823,"<"&(A2+1)) -> 315.98167 | D2: =AVERAGEIFS(Analysis!$E$2:$E$823,Analysis!$B$2:$B$823,">="&A2,Analysis!$B$2:$B$823,"<"&(A2+1)) -> 0.030833333 | E2: =AVERAGEIFS(Analysis!$F$2:$F$823,Analysis!$B$2:$B$823,">="&A2,Analysis!$B$2:$B$823,"<"&(A2+1)) -> 0.1743967 | F2: =D2-($K$8+$K$9*A2) -> 0.22531826 | G2: =E2-($K$10+$K$11*A2) -> 0.031613393 | H2: =D2-($K$5+$K$4*E2) -> 0.14510476 | J2: Annual-mean fit (full calendar years only)
A3: 1960 | B3: =COUNTIFS(Analysis!$B$2:$B$823,">="&A3,Analysis!$B$2:$B$823,"<"&(A3+1)) -> 12 | C3: =AVERAGEIFS(Analysis!$D$2:$D$823,Analysis!$B$2:$B$823,">="&A3,Analysis!$B$2:$B$823,"<"&(A3+1)) -> 316.90833 | D3: =AVERAGEIFS(Analysis!$E$2:$E$823,Analysis!$B$2:$B$823,">="&A3,Analysis!$B$2:$B$823,"<"&(A3+1)) -> -0.025 | E3: =AVERAGEIFS(Analysis!$F$2:$F$823,Analysis!$B$2:$B$823,">="&A3,Analysis!$B$2:$B$823,"<"&(A3+1)) -> 0.17861134 | F3: =D3-($K$8+$K$9*A3) -> 0.15148456 | G3: =E3-($K$10+$K$11*A3) -> 0.029192644 | H3: =D3-($K$5+$K$4*E3) -> 0.077713241 | J3: Years in fit | K3: =COUNT($D$2:$D$68) -> 67
A4: 1961 | B4: =COUNTIFS(Analysis!$B$2:$B$823,">="&A4,Analysis!$B$2:$B$823,"<"&(A4+1)) -> 12 | C4: =AVERAGEIFS(Analysis!$D$2:$D$823,Analysis!$B$2:$B$823,">="&A4,Analysis!$B$2:$B$823,"<"&(A4+1)) -> 317.64333 | D4: =AVERAGEIFS(Analysis!$E$2:$E$823,Analysis!$B$2:$B$823,">="&A4,Analysis!$B$2:$B$823,"<"&(A4+1)) -> 0.056666667 | E4: =AVERAGEIFS(Analysis!$F$2:$F$823,Analysis!$B$2:$B$823,">="&A4,Analysis!$B$2:$B$823,"<"&(A4+1)) -> 0.18196023 | F4: =D4-($K$8+$K$9*A4) -> 0.21515085 | G4: =E4-($K$10+$K$11*A4) -> 0.025906144 | H4: =D4-($K$5+$K$4*E4) -> 0.15019595 | J4: Slope, °C per doubling of CO2 | K4: =SLOPE($D$2:$D$68,$E$2:$E$68) -> 2.7423885
A5: 1962 | B5: =COUNTIFS(Analysis!$B$2:$B$823,">="&A5,Analysis!$B$2:$B$823,"<"&(A5+1)) -> 12 | C5: =AVERAGEIFS(Analysis!$D$2:$D$823,Analysis!$B$2:$B$823,">="&A5,Analysis!$B$2:$B$823,"<"&(A5+1)) -> 318.45333 | D5: =AVERAGEIFS(Analysis!$E$2:$E$823,Analysis!$B$2:$B$823,">="&A5,Analysis!$B$2:$B$823,"<"&(A5+1)) -> 0.030833333 | E5: =AVERAGEIFS(Analysis!$F$2:$F$823,Analysis!$B$2:$B$823,">="&A5,Analysis!$B$2:$B$823,"<"&(A5+1)) -> 0.18563275 | F5: =D5-($K$8+$K$9*A5) -> 0.17131714 | G5: =E5-($K$10+$K$11*A5) -> 0.022943278 | H5: =D5-($K$5+$K$4*E5) -> 0.11429113 | J5: Intercept | K5: =INTERCEPT($D$2:$D$68,$E$2:$E$68) -> -0.59253492
A6: 1963 | B6: =COUNTIFS(Analysis!$B$2:$B$823,">="&A6,Analysis!$B$2:$B$823,"<"&(A6+1)) -> 12 | C6: =AVERAGEIFS(Analysis!$D$2:$D$823,Analysis!$B$2:$B$823,">="&A6,Analysis!$B$2:$B$823,"<"&(A6+1)) -> 318.9925 | D6: =AVERAGEIFS(Analysis!$E$2:$E$823,Analysis!$B$2:$B$823,">="&A6,Analysis!$B$2:$B$823,"<"&(A6+1)) -> 0.054166667 | E6: =AVERAGEIFS(Analysis!$F$2:$F$823,Analysis!$B$2:$B$823,">="&A6,Analysis!$B$2:$B$823,"<"&(A6+1)) -> 0.18806838 | F6: =D6-($K$8+$K$9*A6) -> 0.17665011 | G6: =E6-($K$10+$K$11*A6) -> 0.018743511 | H6: =D6-($K$5+$K$4*E6) -> 0.13094503 | J6: R², annual anomaly vs log2(CO2) | K6: =RSQ($D$2:$D$68,$E$2:$E$68) -> 0.93091854
A7: 1964 | B7: =COUNTIFS(Analysis!$B$2:$B$823,">="&A7,Analysis!$B$2:$B$823,"<"&(A7+1)) -> 12 | C7: =AVERAGEIFS(Analysis!$D$2:$D$823,Analysis!$B$2:$B$823,">="&A7,Analysis!$B$2:$B$823,"<"&(A7+1)) -> 319.62 | D7: =AVERAGEIFS(Analysis!$E$2:$E$823,Analysis!$B$2:$B$823,">="&A7,Analysis!$B$2:$B$823,"<"&(A7+1)) -> -0.19916667 | E7: =AVERAGEIFS(Analysis!$F$2:$F$823,Analysis!$B$2:$B$823,">="&A7,Analysis!$B$2:$B$823,"<"&(A7+1)) -> 0.19090695 | F7: =D7-($K$8+$K$9*A7) -> -0.094683601 | G7: =E7-($K$10+$K$11*A7) -> 0.014946691 | H7: =D7-($K$5+$K$4*E7) -> -0.13017276 | J7: Lag-1 autocorrelation of fit residuals | K7: =CORREL($H$2:$H$67,$H$3:$H$68) -> 0.25356714
A8: 1965 | B8: =COUNTIFS(Analysis!$B$2:$B$823,">="&A8,Analysis!$B$2:$B$823,"<"&(A8+1)) -> 12 | C8: =AVERAGEIFS(Analysis!$D$2:$D$823,Analysis!$B$2:$B$823,">="&A8,Analysis!$B$2:$B$823,"<"&(A8+1)) -> 320.03667 | D8: =AVERAGEIFS(Analysis!$E$2:$E$823,Analysis!$B$2:$B$823,">="&A8,Analysis!$B$2:$B$823,"<"&(A8+1)) -> -0.10666667 | E8: =AVERAGEIFS(Analysis!$F$2:$F$823,Analysis!$B$2:$B$823,">="&A8,Analysis!$B$2:$B$823,"<"&(A8+1)) -> 0.19279249 | F8: =D8-($K$8+$K$9*A8) -> -0.020183973 | G8: =E8-($K$10+$K$11*A8) -> 0.010196842 | H8: =D8-($K$5+$K$4*E8) -> -0.042843646 | J8: Anomaly time trend: intercept | K8: =INTERCEPT($D$2:$D$68,$A$2:$A$68) -> -35.457215
A9: 1966 | B9: =COUNTIFS(Analysis!$B$2:$B$823,">="&A9,Analysis!$B$2:$B$823,"<"&(A9+1)) -> 12 | C9: =AVERAGEIFS(Analysis!$D$2:$D$823,Analysis!$B$2:$B$823,">="&A9,Analysis!$B$2:$B$823,"<"&(A9+1)) -> 321.3675 | D9: =AVERAGEIFS(Analysis!$E$2:$E$823,Analysis!$B$2:$B$823,">="&A9,Analysis!$B$2:$B$823,"<"&(A9+1)) -> -0.0575 | E9: =AVERAGEIFS(Analysis!$F$2:$F$823,Analysis!$B$2:$B$823,">="&A9,Analysis!$B$2:$B$823,"<"&(A9+1)) -> 0.19877222 | F9: =D9-($K$8+$K$9*A9) -> 0.010982321 | G9: =E9-($K$10+$K$11*A9) -> 0.0095411815 | H9: =D9-($K$5+$K$4*E9) -> -0.010075723 | J9: Anomaly time trend: slope (°C/yr) | K9: =SLOPE($D$2:$D$68,$A$2:$A$68) -> 0.018000372
A10: 1967 | B10: =COUNTIFS(Analysis!$B$2:$B$823,">="&A10,Analysis!$B$2:$B$823,"<"&(A10+1)) -> 12 | C10: =AVERAGEIFS(Analysis!$D$2:$D$823,Analysis!$B$2:$B$823,">="&A10,Analysis!$B$2:$B$823,"<"&(A10+1)) -> 322.17917 | D10: =AVERAGEIFS(Analysis!$E$2:$E$823,Analysis!$B$2:$B$823,">="&A10,Analysis!$B$2:$B$823,"<"&(A10+1)) -> -0.024166667 | E10: =AVERAGEIFS(Analysis!$F$2:$F$823,Analysis!$B$2:$B$823,">="&A10,Analysis!$B$2:$B$823,"<"&(A10+1)) -> 0.20241456 | F10: =D10-($K$8+$K$9*A10) -> 0.026315282 | G10: =E10-($K$10+$K$11*A10) -> 0.0065481314 | H10: =D10-($K$5+$K$4*E10) -> 0.013268899 | J10: log2 CO2 time trend: intercept | K10: =INTERCEPT($E$2:$E$68,$A$2:$A$68) -> -12.855946
A11: 1968 | B11: =COUNTIFS(Analysis!$B$2:$B$823,">="&A11,Analysis!$B$2:$B$823,"<"&(A11+1)) -> 12 | C11: =AVERAGEIFS(Analysis!$D$2:$D$823,Analysis!$B$2:$B$823,">="&A11,Analysis!$B$2:$B$823,"<"&(A11+1)) -> 323.05 | D11: =AVERAGEIFS(Analysis!$E$2:$E$823,Analysis!$B$2:$B$823,">="&A11,Analysis!$B$2:$B$823,"<"&(A11+1)) -> -0.0825 | E11: =AVERAGEIFS(Analysis!$F$2:$F$823,Analysis!$B$2:$B$823,">="&A11,Analysis!$B$2:$B$823,"<"&(A11+1)) -> 0.20630941 | F11: =D11-($K$8+$K$9*A11) -> -0.050018424 | G11: =E11-($K$10+$K$11*A11) -> 0.0038075972 | H11: =D11-($K$5+$K$4*E11) -> -0.055745643 | J11: log2 CO2 time trend: slope (/yr) | K11: =SLOPE($E$2:$E$68,$A$2:$A$68) -> 0.0066353903
A12: 1969 | B12: =COUNTIFS(Analysis!$B$2:$B$823,">="&A12,Analysis!$B$2:$B$823,"<"&(A12+1)) -> 12 | C12: =AVERAGEIFS(Analysis!$D$2:$D$823,Analysis!$B$2:$B$823,">="&A12,Analysis!$B$2:$B$823,"<"&(A12+1)) -> 324.62083 | D12: =AVERAGEIFS(Analysis!$E$2:$E$823,Analysis!$B$2:$B$823,">="&A12,Analysis!$B$2:$B$823,"<"&(A12+1)) -> 0.0525 | E12: =AVERAGEIFS(Analysis!$F$2:$F$823,Analysis!$B$2:$B$823,">="&A12,Analysis!$B$2:$B$823,"<"&(A12+1)) -> 0.2133079 | F12: =D12-($K$8+$K$9*A12) -> 0.066981204 | G12: =E12-($K$10+$K$11*A12) -> 0.0041706899 | H12: =D12-($K$5+$K$4*E12) -> 0.060061798
A13: 1970 | B13: =COUNTIFS(Analysis!$B$2:$B$823,">="&A13,Analysis!$B$2:$B$823,"<"&(A13+1)) -> 12 | C13: =AVERAGEIFS(Analysis!$D$2:$D$823,Analysis!$B$2:$B$823,">="&A13,Analysis!$B$2:$B$823,"<"&(A13+1)) -> 325.68167 | D13: =AVERAGEIFS(Analysis!$E$2:$E$823,Analysis!$B$2:$B$823,">="&A13,Analysis!$B$2:$B$823,"<"&(A13+1)) -> 0.0275 | E13: =AVERAGEIFS(Analysis!$F$2:$F$823,Analysis!$B$2:$B$823,">="&A13,Analysis!$B$2:$B$823,"<"&(A13+1)) -> 0.21801538 | F13: =D13-($K$8+$K$9*A13) -> 0.023980831 | G13: =E13-($K$10+$K$11*A13) -> 0.002242785 | H13: =D13-($K$5+$K$4*E13) -> 0.022152044 | J13: DETRENDED TEST: r between residual series | K13: =CORREL($F$2:$F$68,$G$2:$G$68) -> 0.63587131
A14: 1971 | B14: =COUNTIFS(Analysis!$B$2:$B$823,">="&A14,Analysis!$B$2:$B$823,"<"&(A14+1)) -> 12 | C14: =AVERAGEIFS(Analysis!$D$2:$D$823,Analysis!$B$2:$B$823,">="&A14,Analysis!$B$2:$B$823,"<"&(A14+1)) -> 326.32 | D14: =AVERAGEIFS(Analysis!$E$2:$E$823,Analysis!$B$2:$B$823,">="&A14,Analysis!$B$2:$B$823,"<"&(A14+1)) -> -0.079166667 | E14: =AVERAGEIFS(Analysis!$F$2:$F$823,Analysis!$B$2:$B$823,">="&A14,Analysis!$B$2:$B$823,"<"&(A14+1)) -> 0.22084049 | F14: =D14-($K$8+$K$9*A14) -> -0.10068621 | G14: =E14-($K$10+$K$11*A14) -> -0.0015674995 | H14: =D14-($K$5+$K$4*E14) -> -0.09226216
A15: 1972 | B15: =COUNTIFS(Analysis!$B$2:$B$823,">="&A15,Analysis!$B$2:$B$823,"<"&(A15+1)) -> 12 | C15: =AVERAGEIFS(Analysis!$D$2:$D$823,Analysis!$B$2:$B$823,">="&A15,Analysis!$B$2:$B$823,"<"&(A15+1)) -> 327.45667 | D15: =AVERAGEIFS(Analysis!$E$2:$E$823,Analysis!$B$2:$B$823,">="&A15,Analysis!$B$2:$B$823,"<"&(A15+1)) -> 0.0091666667 | E15: =AVERAGEIFS(Analysis!$F$2:$F$823,Analysis!$B$2:$B$823,">="&A15,Analysis!$B$2:$B$823,"<"&(A15+1)) -> 0.22586053 | F15: =D15-($K$8+$K$9*A15) -> -0.030353247 | G15: =E15-($K$10+$K$11*A15) -> -0.0031828518 | H15: =D15-($K$5+$K$4*E15) -> -0.017695721 | J15: Detrended R² | K15: =RSQ($F$2:$F$68,$G$2:$G$68) -> 0.40433233
A16: 1973 | B16: =COUNTIFS(Analysis!$B$2:$B$823,">="&A16,Analysis!$B$2:$B$823,"<"&(A16+1)) -> 12 | C16: =AVERAGEIFS(Analysis!$D$2:$D$823,Analysis!$B$2:$B$823,">="&A16,Analysis!$B$2:$B$823,"<"&(A16+1)) -> 329.68167 | D16: =AVERAGEIFS(Analysis!$E$2:$E$823,Analysis!$B$2:$B$823,">="&A16,Analysis!$B$2:$B$823,"<"&(A16+1)) -> 0.16083333 | E16: =AVERAGEIFS(Analysis!$F$2:$F$823,Analysis!$B$2:$B$823,">="&A16,Analysis!$B$2:$B$823,"<"&(A16+1)) -> 0.23562788 | F16: =D16-($K$8+$K$9*A16) -> 0.10331305 | G16: =E16-($K$10+$K$11*A16) -> -5.0888931e-05 | H16: =D16-($K$5+$K$4*E16) -> 0.10718507
A17: 1974 | B17: =COUNTIFS(Analysis!$B$2:$B$823,">="&A17,Analysis!$B$2:$B$823,"<"&(A17+1)) -> 12 | C17: =AVERAGEIFS(Analysis!$D$2:$D$823,Analysis!$B$2:$B$823,">="&A17,Analysis!$B$2:$B$823,"<"&(A17+1)) -> 330.19333 | D17: =AVERAGEIFS(Analysis!$E$2:$E$823,Analysis!$B$2:$B$823,">="&A17,Analysis!$B$2:$B$823,"<"&(A17+1)) -> -0.071666667 | E17: =AVERAGEIFS(Analysis!$F$2:$F$823,Analysis!$B$2:$B$823,">="&A17,Analysis!$B$2:$B$823,"<"&(A17+1)) -> 0.23785982 | F17: =D17-($K$8+$K$9*A17) -> -0.14718733 | G17: =E17-($K$10+$K$11*A17) -> -0.004454341 | H17: =D17-($K$5+$K$4*E17) -> -0.13143577 | J17: Naive OLS standard error of slope | K17: =INDEX(LINEST($D$2:$D$68,$E$2:$E$68,TRUE(),TRUE()),2,1) -> 0.092661048
A18: 1975 | B18: =COUNTIFS(Analysis!$B$2:$B$823,">="&A18,Analysis!$B$2:$B$823,"<"&(A18+1)) -> 12 | C18: =AVERAGEIFS(Analysis!$D$2:$D$823,Analysis!$B$2:$B$823,">="&A18,Analysis!$B$2:$B$823,"<"&(A18+1)) -> 331.1275 | D18: =AVERAGEIFS(Analysis!$E$2:$E$823,Analysis!$B$2:$B$823,">="&A18,Analysis!$B$2:$B$823,"<"&(A18+1)) -> -0.013333333 | E18: =AVERAGEIFS(Analysis!$F$2:$F$823,Analysis!$B$2:$B$823,">="&A18,Analysis!$B$2:$B$823,"<"&(A18+1)) -> 0.24193918 | F18: =D18-($K$8+$K$9*A18) -> -0.10685436 | G18: =E18-($K$10+$K$11*A18) -> -0.007010368 | H18: =D18-($K$5+$K$4*E18) -> -0.084289639 | J18: AR(1) inflation factor √((1+ρ)/(1-ρ)) | K18: =SQRT((1+K7)/(1-K7)) -> 1.2959207
A19: 1976 | B19: =COUNTIFS(Analysis!$B$2:$B$823,">="&A19,Analysis!$B$2:$B$823,"<"&(A19+1)) -> 12 | C19: =AVERAGEIFS(Analysis!$D$2:$D$823,Analysis!$B$2:$B$823,">="&A19,Analysis!$B$2:$B$823,"<"&(A19+1)) -> 332.02583 | D19: =AVERAGEIFS(Analysis!$E$2:$E$823,Analysis!$B$2:$B$823,">="&A19,Analysis!$B$2:$B$823,"<"&(A19+1)) -> -0.0975 | E19: =AVERAGEIFS(Analysis!$F$2:$F$823,Analysis!$B$2:$B$823,">="&A19,Analysis!$B$2:$B$823,"<"&(A19+1)) -> 0.24584257 | F19: =D19-($K$8+$K$9*A19) -> -0.2090214 | G19: =E19-($K$10+$K$11*A19) -> -0.0097423662 | H19: =D19-($K$5+$K$4*E19) -> -0.17916092 | J19: Adjusted standard error | K19: =K17*K18 -> 0.12008137
A20: 1977 | B20: =COUNTIFS(Analysis!$B$2:$B$823,">="&A20,Analysis!$B$2:$B$823,"<"&(A20+1)) -> 12 | C20: =AVERAGEIFS(Analysis!$D$2:$D$823,Analysis!$B$2:$B$823,">="&A20,Analysis!$B$2:$B$823,"<"&(A20+1)) -> 333.84417 | D20: =AVERAGEIFS(Analysis!$E$2:$E$823,Analysis!$B$2:$B$823,">="&A20,Analysis!$B$2:$B$823,"<"&(A20+1)) -> 0.17833333 | E20: =AVERAGEIFS(Analysis!$F$2:$F$823,Analysis!$B$2:$B$823,">="&A20,Analysis!$B$2:$B$823,"<"&(A20+1)) -> 0.25372587 | F20: =D20-($K$8+$K$9*A20) -> 0.048811557 | G20: =E20-($K$10+$K$11*A20) -> -0.0084944611 | H20: =D20-($K$5+$K$4*E20) -> 0.075053352 | J20: 95% interval, low / high (°C per doubling) | K20: =K4-1.96*K19 -> 2.507029 | L20: =K4+1.96*K19 -> 2.977748
A21: 1978 | B21: =COUNTIFS(Analysis!$B$2:$B$823,">="&A21,Analysis!$B$2:$B$823,"<"&(A21+1)) -> 12 | C21: =AVERAGEIFS(Analysis!$D$2:$D$823,Analysis!$B$2:$B$823,">="&A21,Analysis!$B$2:$B$823,"<"&(A21+1)) -> 335.415 | D21: =AVERAGEIFS(Analysis!$E$2:$E$823,Analysis!$B$2:$B$823,">="&A21,Analysis!$B$2:$B$823,"<"&(A21+1)) -> 0.066666667 | E21: =AVERAGEIFS(Analysis!$F$2:$F$823,Analysis!$B$2:$B$823,">="&A21,Analysis!$B$2:$B$823,"<"&(A21+1)) -> 0.26049698 | F21: =D21-($K$8+$K$9*A21) -> -0.080855482 | G21: =E21-($K$10+$K$11*A21) -> -0.0083587422 | H21: =D21-($K$5+$K$4*E21) -> -0.055182327 | J21: Split sample: slope 1959-1991 / 1992-2025 | K21: =SLOPE($D$2:$D$34,$E$2:$E$34) -> 2.573599 | L21: =SLOPE($D$35:$D$68,$E$35:$E$68) -> 3.1905042
A22: 1979 | B22: =COUNTIFS(Analysis!$B$2:$B$823,">="&A22,Analysis!$B$2:$B$823,"<"&(A22+1)) -> 12 | C22: =AVERAGEIFS(Analysis!$D$2:$D$823,Analysis!$B$2:$B$823,">="&A22,Analysis!$B$2:$B$823,"<"&(A22+1)) -> 336.835 | D22: =AVERAGEIFS(Analysis!$E$2:$E$823,Analysis!$B$2:$B$823,">="&A22,Analysis!$B$2:$B$823,"<"&(A22+1)) -> 0.16416667 | E22: =AVERAGEIFS(Analysis!$F$2:$F$823,Analysis!$B$2:$B$823,">="&A22,Analysis!$B$2:$B$823,"<"&(A22+1)) -> 0.26659554 | F22: =D22-($K$8+$K$9*A22) -> -0.0013558544 | G22: =E22-($K$10+$K$11*A22) -> -0.008895571 | H22: =D22-($K$5+$K$4*E22) -> 0.025593049 | J22: Split difference ÷ combined AR(1)-adjusted SE (t-like) | K22: =(L21-K21)/SQRT((INDEX(LINEST($D$2:$D$34,$E$2:$E$34,TRUE(),TRUE()),2,1)*K18)^2+(INDEX(LINEST($D$35:$D$68,$E$35:$E$68,TRUE(),TRUE()),2,1)*K18)^2) -> 1.257008
A23: 1980 | B23: =COUNTIFS(Analysis!$B$2:$B$823,">="&A23,Analysis!$B$2:$B$823,"<"&(A23+1)) -> 12 | C23: =AVERAGEIFS(Analysis!$D$2:$D$823,Analysis!$B$2:$B$823,">="&A23,Analysis!$B$2:$B$823,"<"&(A23+1)) -> 338.7625 | D23: =AVERAGEIFS(Analysis!$E$2:$E$823,Analysis!$B$2:$B$823,">="&A23,Analysis!$B$2:$B$823,"<"&(A23+1)) -> 0.25583333 | E23: =AVERAGEIFS(Analysis!$F$2:$F$823,Analysis!$B$2:$B$823,">="&A23,Analysis!$B$2:$B$823,"<"&(A23+1)) -> 0.27482719 | F23: =D23-($K$8+$K$9*A23) -> 0.07231044 | G23: =E23-($K$10+$K$11*A23) -> -0.0072993114 | H23: =D23-($K$5+$K$4*E23) -> 0.094685333 | J23: Summary of central results
A24: 1981 | B24: =COUNTIFS(Analysis!$B$2:$B$823,">="&A24,Analysis!$B$2:$B$823,"<"&(A24+1)) -> 12 | C24: =AVERAGEIFS(Analysis!$D$2:$D$823,Analysis!$B$2:$B$823,">="&A24,Analysis!$B$2:$B$823,"<"&(A24+1)) -> 340.12 | D24: =AVERAGEIFS(Analysis!$E$2:$E$823,Analysis!$B$2:$B$823,">="&A24,Analysis!$B$2:$B$823,"<"&(A24+1)) -> 0.32333333 | E24: =AVERAGEIFS(Analysis!$F$2:$F$823,Analysis!$B$2:$B$823,">="&A24,Analysis!$B$2:$B$823,"<"&(A24+1)) -> 0.28059167 | F24: =D24-($K$8+$K$9*A24) -> 0.12181007 | G24: =E24-($K$10+$K$11*A24) -> -0.008170222 | H24: =D24-($K$5+$K$4*E24) -> 0.14637689 | J24: Monthly fit: °C per CO2 doubling | K24: Annual fit: °C per CO2 doubling | L24: Detrended annual r
A25: 1982 | B25: =COUNTIFS(Analysis!$B$2:$B$823,">="&A25,Analysis!$B$2:$B$823,"<"&(A25+1)) -> 12 | C25: =AVERAGEIFS(Analysis!$D$2:$D$823,Analysis!$B$2:$B$823,">="&A25,Analysis!$B$2:$B$823,"<"&(A25+1)) -> 341.47833 | D25: =AVERAGEIFS(Analysis!$E$2:$E$823,Analysis!$B$2:$B$823,">="&A25,Analysis!$B$2:$B$823,"<"&(A25+1)) -> 0.13916667 | E25: =AVERAGEIFS(Analysis!$F$2:$F$823,Analysis!$B$2:$B$823,">="&A25,Analysis!$B$2:$B$823,"<"&(A25+1)) -> 0.28634093 | F25: =D25-($K$8+$K$9*A25) -> -0.080356972 | G25: =E25-($K$10+$K$11*A25) -> -0.0090563455 | H25: =D25-($K$5+$K$4*E25) -> -0.053556499 | J25: =Analysis!I11 -> 2.7335713 | K25: =K4 -> 2.7423885 | L25: =K13 -> 0.63587131
A26: 1983 | B26: =COUNTIFS(Analysis!$B$2:$B$823,">="&A26,Analysis!$B$2:$B$823,"<"&(A26+1)) -> 12 | C26: =AVERAGEIFS(Analysis!$D$2:$D$823,Analysis!$B$2:$B$823,">="&A26,Analysis!$B$2:$B$823,"<"&(A26+1)) -> 343.1525 | D26: =AVERAGEIFS(Analysis!$E$2:$E$823,Analysis!$B$2:$B$823,">="&A26,Analysis!$B$2:$B$823,"<"&(A26+1)) -> 0.315 | E26: =AVERAGEIFS(Analysis!$F$2:$F$823,Analysis!$B$2:$B$823,">="&A26,Analysis!$B$2:$B$823,"<"&(A26+1)) -> 0.293402 | F26: =D26-($K$8+$K$9*A26) -> 0.077475989 | G26: =E26-($K$10+$K$11*A26) -> -0.0086306664 | H26: =D26-($K$5+$K$4*E26) -> 0.10291264 | J26: 822 months, 1958-2026 | K26: 67 full years, 1959-2025 | L26: linear time trend removed from both series
A27: 1984 | B27: =COUNTIFS(Analysis!$B$2:$B$823,">="&A27,Analysis!$B$2:$B$823,"<"&(A27+1)) -> 12 | C27: =AVERAGEIFS(Analysis!$D$2:$D$823,Analysis!$B$2:$B$823,">="&A27,Analysis!$B$2:$B$823,"<"&(A27+1)) -> 344.86667 | D27: =AVERAGEIFS(Analysis!$E$2:$E$823,Analysis!$B$2:$B$823,">="&A27,Analysis!$B$2:$B$823,"<"&(A27+1)) -> 0.155 | E27: =AVERAGEIFS(Analysis!$F$2:$F$823,Analysis!$B$2:$B$823,">="&A27,Analysis!$B$2:$B$823,"<"&(A27+1)) -> 0.30058891 | F27: =D27-($K$8+$K$9*A27) -> -0.10052438 | G27: =E27-($K$10+$K$11*A27) -> -0.0080791536 | H27: =D27-($K$5+$K$4*E27) -> -0.076796642 | J27: Caution: these are descriptive observational regressions over 1958-2026, not estimates of equilibrium climate sensitivity.
A28: 1985 | B28: =COUNTIFS(Analysis!$B$2:$B$823,">="&A28,Analysis!$B$2:$B$823,"<"&(A28+1)) -> 12 | C28: =AVERAGEIFS(Analysis!$D$2:$D$823,Analysis!$B$2:$B$823,">="&A28,Analysis!$B$2:$B$823,"<"&(A28+1)) -> 346.35167 | D28: =AVERAGEIFS(Analysis!$E$2:$E$823,Analysis!$B$2:$B$823,">="&A28,Analysis!$B$2:$B$823,"<"&(A28+1)) -> 0.11833333 | E28: =AVERAGEIFS(Analysis!$F$2:$F$823,Analysis!$B$2:$B$823,">="&A28,Analysis!$B$2:$B$823,"<"&(A28+1)) -> 0.3067888 | F28: =D28-($K$8+$K$9*A28) -> -0.15519142 | G28: =E28-($K$10+$K$11*A28) -> -0.0085146485 | H28: =D28-($K$5+$K$4*E28) -> -0.13046583 | J28: See the Solar, ENSO, Volcanic and Forcing tabs for the natural-variability controls and the full-forcing comparison.
A29: 1986 | B29: =COUNTIFS(Analysis!$B$2:$B$823,">="&A29,Analysis!$B$2:$B$823,"<"&(A29+1)) -> 12 | C29: =AVERAGEIFS(Analysis!$D$2:$D$823,Analysis!$B$2:$B$823,">="&A29,Analysis!$B$2:$B$823,"<"&(A29+1)) -> 347.6075 | D29: =AVERAGEIFS(Analysis!$E$2:$E$823,Analysis!$B$2:$B$823,">="&A29,Analysis!$B$2:$B$823,"<"&(A29+1)) -> 0.18 | E29: =AVERAGEIFS(Analysis!$F$2:$F$823,Analysis!$B$2:$B$823,">="&A29,Analysis!$B$2:$B$823,"<"&(A29+1)) -> 0.31201398 | F29: =D29-($K$8+$K$9*A29) -> -0.11152513 | G29: =E29-($K$10+$K$11*A29) -> -0.009924862 | H29: =D29-($K$5+$K$4*E29) -> -0.083128628
A30: 1987 | B30: =COUNTIFS(Analysis!$B$2:$B$823,">="&A30,Analysis!$B$2:$B$823,"<"&(A30+1)) -> 12 | C30: =AVERAGEIFS(Analysis!$D$2:$D$823,Analysis!$B$2:$B$823,">="&A30,Analysis!$B$2:$B$823,"<"&(A30+1)) -> 349.31167 | D30: =AVERAGEIFS(Analysis!$E$2:$E$823,Analysis!$B$2:$B$823,">="&A30,Analysis!$B$2:$B$823,"<"&(A30+1)) -> 0.32166667 | E30: =AVERAGEIFS(Analysis!$F$2:$F$823,Analysis!$B$2:$B$823,">="&A30,Analysis!$B$2:$B$823,"<"&(A30+1)) -> 0.31907046 | F30: =D30-($K$8+$K$9*A30) -> 0.012141166 | G30: =E30-($K$10+$K$11*A30) -> -0.0095037704 | H30: =D30-($K$5+$K$4*E30) -> 0.039186424 | J30: How to read this sheet
A31: 1988 | B31: =COUNTIFS(Analysis!$B$2:$B$823,">="&A31,Analysis!$B$2:$B$823,"<"&(A31+1)) -> 12 | C31: =AVERAGEIFS(Analysis!$D$2:$D$823,Analysis!$B$2:$B$823,">="&A31,Analysis!$B$2:$B$823,"<"&(A31+1)) -> 351.69 | D31: =AVERAGEIFS(Analysis!$E$2:$E$823,Analysis!$B$2:$B$823,">="&A31,Analysis!$B$2:$B$823,"<"&(A31+1)) -> 0.39 | E31: =AVERAGEIFS(Analysis!$F$2:$F$823,Analysis!$B$2:$B$823,">="&A31,Analysis!$B$2:$B$823,"<"&(A31+1)) -> 0.32886052 | F31: =D31-($K$8+$K$9*A31) -> 0.062474127 | G31: =E31-($K$10+$K$11*A31) -> -0.006349102 | H31: =D31-($K$5+$K$4*E31) -> 0.080671613 | J31: 1. Annual means remove most of the month-to-month autocorrelation (lag-1 falls from ~0.64 monthly to ~0.25), so the 67 years are closer to independent observations than the 822 months.
A32: 1989 | B32: =COUNTIFS(Analysis!$B$2:$B$823,">="&A32,Analysis!$B$2:$B$823,"<"&(A32+1)) -> 12 | C32: =AVERAGEIFS(Analysis!$D$2:$D$823,Analysis!$B$2:$B$823,">="&A32,Analysis!$B$2:$B$823,"<"&(A32+1)) -> 353.205 | D32: =AVERAGEIFS(Analysis!$E$2:$E$823,Analysis!$B$2:$B$823,">="&A32,Analysis!$B$2:$B$823,"<"&(A32+1)) -> 0.27416667 | E32: =AVERAGEIFS(Analysis!$F$2:$F$823,Analysis!$B$2:$B$823,">="&A32,Analysis!$B$2:$B$823,"<"&(A32+1)) -> 0.33505818 | F32: =D32-($K$8+$K$9*A32) -> -0.071359579 | G32: =E32-($K$10+$K$11*A32) -> -0.0067868342 | H32: =D32-($K$5+$K$4*E32) -> -0.052158107 | J32: 2. The detrended test answers "are these just two things rising with time?": a straight-line time trend is removed from BOTH series and the leftover wiggles are correlated. A high r here cannot be produced by a shared trend.
A33: 1990 | B33: =COUNTIFS(Analysis!$B$2:$B$823,">="&A33,Analysis!$B$2:$B$823,"<"&(A33+1)) -> 12 | C33: =AVERAGEIFS(Analysis!$D$2:$D$823,Analysis!$B$2:$B$823,">="&A33,Analysis!$B$2:$B$823,"<"&(A33+1)) -> 354.4525 | D33: =AVERAGEIFS(Analysis!$E$2:$E$823,Analysis!$B$2:$B$823,">="&A33,Analysis!$B$2:$B$823,"<"&(A33+1)) -> 0.44916667 | E33: =AVERAGEIFS(Analysis!$F$2:$F$823,Analysis!$B$2:$B$823,">="&A33,Analysis!$B$2:$B$823,"<"&(A33+1)) -> 0.34014661 | F33: =D33-($K$8+$K$9*A33) -> 0.085640048 | G33: =E33-($K$10+$K$11*A33) -> -0.0083337973 | H33: =D33-($K$5+$K$4*E33) -> 0.10888745 | J33: 3. Tests deliberately omitted: regressing anomaly on CO2 plus time (CO2 and time correlate at ~0.99 here, so the coefficients are unstable and uninformative), and 5- or 10-year differences (CO2 moves only ~0.03-0.07 doublings per step, so ENSO noise swamps the signal and R² collapses regardless of the true relationship).
A34: 1991 | B34: =COUNTIFS(Analysis!$B$2:$B$823,">="&A34,Analysis!$B$2:$B$823,"<"&(A34+1)) -> 12 | C34: =AVERAGEIFS(Analysis!$D$2:$D$823,Analysis!$B$2:$B$823,">="&A34,Analysis!$B$2:$B$823,"<"&(A34+1)) -> 355.70417 | D34: =AVERAGEIFS(Analysis!$E$2:$E$823,Analysis!$B$2:$B$823,">="&A34,Analysis!$B$2:$B$823,"<"&(A34+1)) -> 0.4075 | E34: =AVERAGEIFS(Analysis!$F$2:$F$823,Analysis!$B$2:$B$823,">="&A34,Analysis!$B$2:$B$823,"<"&(A34+1)) -> 0.34522236 | F34: =D34-($K$8+$K$9*A34) -> 0.025973009 | G34: =E34-($K$10+$K$11*A34) -> -0.0098934366 | H34: =D34-($K$5+$K$4*E34) -> 0.053301102 | J34: 4. Uncertainty: the naive OLS standard error is inflated by the AR(1) factor (Grok/GPT review, Sept 2026); the resulting 95% interval (~2.5 to 3.0 °C per doubling) reflects time-series error only, not forcing or dataset uncertainty. Newey-West standard errors with 1-6 lags give 0.120-0.126, so the AR(1) heuristic is adequate here. The split-sample slopes (1959-1991 vs 1992-2025) differ (~2.6 vs ~3.2) but only by ~1.3 combined adjusted SEs (K22), so the difference is suggestive, not established. The direction is what the forcing data predict: net anthropogenic forcing grew faster than CO2 alone once aerosol offset stopped growing (Forcing tab, T42:U42), which is a reason to prefer the anthropogenic-ERF regression over the CO2 proxy for any response estimate.
A35: 1992 | B35: =COUNTIFS(Analysis!$B$2:$B$823,">="&A35,Analysis!$B$2:$B$823,"<"&(A35+1)) -> 12 | C35: =AVERAGEIFS(Analysis!$D$2:$D$823,Analysis!$B$2:$B$823,">="&A35,Analysis!$B$2:$B$823,"<"&(A35+1)) -> 356.545 | D35: =AVERAGEIFS(Analysis!$E$2:$E$823,Analysis!$B$2:$B$823,">="&A35,Analysis!$B$2:$B$823,"<"&(A35+1)) -> 0.22416667 | E35: =AVERAGEIFS(Analysis!$F$2:$F$823,Analysis!$B$2:$B$823,">="&A35,Analysis!$B$2:$B$823,"<"&(A35+1)) -> 0.34862967 | F35: =D35-($K$8+$K$9*A35) -> -0.1753607 | G35: =E35-($K$10+$K$11*A35) -> -0.013121512 | H35: =D35-($K$5+$K$4*E35) -> -0.13937641 | J35: 5. None of these fits is a climate sensitivity estimate. They describe the observed 1958-2026 co-variation; other forcings (methane, aerosols, solar, volcanic) and ocean lag are not separated out.
A36: 1993 | B36: =COUNTIFS(Analysis!$B$2:$B$823,">="&A36,Analysis!$B$2:$B$823,"<"&(A36+1)) -> 12 | C36: =AVERAGEIFS(Analysis!$D$2:$D$823,Analysis!$B$2:$B$823,">="&A36,Analysis!$B$2:$B$823,"<"&(A36+1)) -> 357.215 | D36: =AVERAGEIFS(Analysis!$E$2:$E$823,Analysis!$B$2:$B$823,">="&A36,Analysis!$B$2:$B$823,"<"&(A36+1)) -> 0.23333333 | E36: =AVERAGEIFS(Analysis!$F$2:$F$823,Analysis!$B$2:$B$823,">="&A36,Analysis!$B$2:$B$823,"<"&(A36+1)) -> 0.3513444 | F36: =D36-($K$8+$K$9*A36) -> -0.1841944 | G36: =E36-($K$10+$K$11*A36) -> -0.017042172 | H36: =D36-($K$5+$K$4*E36) -> -0.13765459
A37: 1994 | B37: =COUNTIFS(Analysis!$B$2:$B$823,">="&A37,Analysis!$B$2:$B$823,"<"&(A37+1)) -> 12 | C37: =AVERAGEIFS(Analysis!$D$2:$D$823,Analysis!$B$2:$B$823,">="&A37,Analysis!$B$2:$B$823,"<"&(A37+1)) -> 358.95917 | D37: =AVERAGEIFS(Analysis!$E$2:$E$823,Analysis!$B$2:$B$823,">="&A37,Analysis!$B$2:$B$823,"<"&(A37+1)) -> 0.31583333 | E37: =AVERAGEIFS(Analysis!$F$2:$F$823,Analysis!$B$2:$B$823,">="&A37,Analysis!$B$2:$B$823,"<"&(A37+1)) -> 0.35837405 | F37: =D37-($K$8+$K$9*A37) -> -0.11969477 | G37: =E37-($K$10+$K$11*A37) -> -0.016647912 | H37: =D37-($K$5+$K$4*E37) -> -0.074432624
A38: 1995 | B38: =COUNTIFS(Analysis!$B$2:$B$823,">="&A38,Analysis!$B$2:$B$823,"<"&(A38+1)) -> 12 | C38: =AVERAGEIFS(Analysis!$D$2:$D$823,Analysis!$B$2:$B$823,">="&A38,Analysis!$B$2:$B$823,"<"&(A38+1)) -> 360.96833 | D38: =AVERAGEIFS(Analysis!$E$2:$E$823,Analysis!$B$2:$B$823,">="&A38,Analysis!$B$2:$B$823,"<"&(A38+1)) -> 0.4475 | E38: =AVERAGEIFS(Analysis!$F$2:$F$823,Analysis!$B$2:$B$823,">="&A38,Analysis!$B$2:$B$823,"<"&(A38+1)) -> 0.36642609 | F38: =D38-($K$8+$K$9*A38) -> -0.0060284806 | G38: =E38-($K$10+$K$11*A38) -> -0.015231268 | H38: =D38-($K$5+$K$4*E38) -> 0.035152237
A39: 1996 | B39: =COUNTIFS(Analysis!$B$2:$B$823,">="&A39,Analysis!$B$2:$B$823,"<"&(A39+1)) -> 12 | C39: =AVERAGEIFS(Analysis!$D$2:$D$823,Analysis!$B$2:$B$823,">="&A39,Analysis!$B$2:$B$823,"<"&(A39+1)) -> 362.74333 | D39: =AVERAGEIFS(Analysis!$E$2:$E$823,Analysis!$B$2:$B$823,">="&A39,Analysis!$B$2:$B$823,"<"&(A39+1)) -> 0.33416667 | E39: =AVERAGEIFS(Analysis!$F$2:$F$823,Analysis!$B$2:$B$823,">="&A39,Analysis!$B$2:$B$823,"<"&(A39+1)) -> 0.37350294 | F39: =D39-($K$8+$K$9*A39) -> -0.13736219 | G39: =E39-($K$10+$K$11*A39) -> -0.014789809 | H39: =D39-($K$5+$K$4*E39) -> -0.097588567
A40: 1997 | B40: =COUNTIFS(Analysis!$B$2:$B$823,">="&A40,Analysis!$B$2:$B$823,"<"&(A40+1)) -> 12 | C40: =AVERAGEIFS(Analysis!$D$2:$D$823,Analysis!$B$2:$B$823,">="&A40,Analysis!$B$2:$B$823,"<"&(A40+1)) -> 363.87667 | D40: =AVERAGEIFS(Analysis!$E$2:$E$823,Analysis!$B$2:$B$823,">="&A40,Analysis!$B$2:$B$823,"<"&(A40+1)) -> 0.4675 | E40: =AVERAGEIFS(Analysis!$F$2:$F$823,Analysis!$B$2:$B$823,">="&A40,Analysis!$B$2:$B$823,"<"&(A40+1)) -> 0.37800252 | F40: =D40-($K$8+$K$9*A40) -> -0.022029226 | G40: =E40-($K$10+$K$11*A40) -> -0.016925611 | H40: =D40-($K$5+$K$4*E40) -> 0.023405149
...

Sheet Solar
A1: Month/Year | B1: Anomaly (°C) | C1: log2(CO2/280) | D1: TSI (W/m²), NRLTSI2 | F1: Year | G1: Mean anomaly (°C) | H1: Mean log2(CO2/280) | I1: Mean TSI (W/m²) | J1: CO2-fit residual (from Annual!H) | K1: Multiple-regression fitted anomaly
A2: =Analysis!A2 -> 3/1958 | B2: =Analysis!E2 -> 0.08 | C2: =Analysis!F2 -> 0.17317313 | D2: 1361.03 | F2: 1959 | G2: =AVERAGEIFS(Analysis!$E$2:$E$823,Analysis!$B$2:$B$823,">="&F2,Analysis!$B$2:$B$823,"<"&(F2+1)) -> 0.030833333 | H2: =AVERAGEIFS(Analysis!$F$2:$F$823,Analysis!$B$2:$B$823,">="&F2,Analysis!$B$2:$B$823,"<"&(F2+1)) -> 0.1743967 | I2: =AVERAGEIFS($D$2:$D$791,Analysis!$B$2:$B$791,">="&F2,Analysis!$B$2:$B$791,"<"&(F2+1)) -> 1361.565 | J2: =Annual!H2 -> 0.14510476 | K2: =$O$16+$O$17*H2+$O$18*I2 -> -0.072108867 | N2: Assumptions
A3: =Analysis!A3 -> 4/1958 | B3: =Analysis!E3 -> 0.01 | C3: =Analysis!F3 -> 0.18110255 | D3: 1361.85 | F3: 1960 | G3: =AVERAGEIFS(Analysis!$E$2:$E$823,Analysis!$B$2:$B$823,">="&F3,Analysis!$B$2:$B$823,"<"&(F3+1)) -> -0.025 | H3: =AVERAGEIFS(Analysis!$F$2:$F$823,Analysis!$B$2:$B$823,">="&F3,Analysis!$B$2:$B$823,"<"&(F3+1)) -> 0.17861134 | I3: =AVERAGEIFS($D$2:$D$791,Analysis!$B$2:$B$791,">="&F3,Analysis!$B$2:$B$791,"<"&(F3+1)) -> 1361.4283 | J3: =Annual!H3 -> 0.077713241 | K3: =$O$16+$O$17*H3+$O$18*I3 -> -0.070102138 | N3: Planetary albedo (fraction reflected) | O3: 0.3
A4: =Analysis!A4 -> 5/1958 | B4: =Analysis!E4 -> 0.06 | C4: =Analysis!F4 -> 0.1813752 | D4: 1362.07 | F4: 1961 | G4: =AVERAGEIFS(Analysis!$E$2:$E$823,Analysis!$B$2:$B$823,">="&F4,Analysis!$B$2:$B$823,"<"&(F4+1)) -> 0.056666667 | H4: =AVERAGEIFS(Analysis!$F$2:$F$823,Analysis!$B$2:$B$823,">="&F4,Analysis!$B$2:$B$823,"<"&(F4+1)) -> 0.18196023 | I4: =AVERAGEIFS($D$2:$D$791,Analysis!$B$2:$B$791,">="&F4,Analysis!$B$2:$B$791,"<"&(F4+1)) -> 1360.995 | J4: =Annual!H4 -> 0.15019595 | K4: =$O$16+$O$17*H4+$O$18*I4 -> -0.090402125 | N4: CO2 forcing coefficient (W/m² per ln) | O4: 5.35
A5: =Analysis!A5 -> 6/1958 | B5: =Analysis!E5 -> -0.09 | C5: =Analysis!F5 -> 0.18028428 | D5: 1362.08 | F5: 1962 | G5: =AVERAGEIFS(Analysis!$E$2:$E$823,Analysis!$B$2:$B$823,">="&F5,Analysis!$B$2:$B$823,"<"&(F5+1)) -> 0.030833333 | H5: =AVERAGEIFS(Analysis!$F$2:$F$823,Analysis!$B$2:$B$823,">="&F5,Analysis!$B$2:$B$823,"<"&(F5+1)) -> 0.18563275 | I5: =AVERAGEIFS($D$2:$D$791,Analysis!$B$2:$B$791,">="&F5,Analysis!$B$2:$B$791,"<"&(F5+1)) -> 1360.7975 | J5: =Annual!H5 -> 0.11429113 | K5: =$O$16+$O$17*H5+$O$18*I5 -> -0.093940204
A6: =Analysis!A6 -> 7/1958 | B6: =Analysis!E6 -> 0.05 | C6: =Analysis!F6 -> 0.1739041 | D6: 1361.68 | F6: 1963 | G6: =AVERAGEIFS(Analysis!$E$2:$E$823,Analysis!$B$2:$B$823,">="&F6,Analysis!$B$2:$B$823,"<"&(F6+1)) -> 0.054166667 | H6: =AVERAGEIFS(Analysis!$F$2:$F$823,Analysis!$B$2:$B$823,">="&F6,Analysis!$B$2:$B$823,"<"&(F6+1)) -> 0.18806838 | I6: =AVERAGEIFS($D$2:$D$791,Analysis!$B$2:$B$791,">="&F6,Analysis!$B$2:$B$791,"<"&(F6+1)) -> 1360.7333 | J6: =Annual!H6 -> 0.13094503 | K6: =$O$16+$O$17*H6+$O$18*I6 -> -0.091781846 | N6: Does the Sun explain it? (annual means, 1959-2023)
A7: =Analysis!A7 -> 8/1958 | B7: =Analysis!E7 -> -0.05 | C7: =Analysis!F7 -> 0.16960437 | D7: 1361.92 | F7: 1964 | G7: =AVERAGEIFS(Analysis!$E$2:$E$823,Analysis!$B$2:$B$823,">="&F7,Analysis!$B$2:$B$823,"<"&(F7+1)) -> -0.19916667 | H7: =AVERAGEIFS(Analysis!$F$2:$F$823,Analysis!$B$2:$B$823,">="&F7,Analysis!$B$2:$B$823,"<"&(F7+1)) -> 0.19090695 | I7: =AVERAGEIFS($D$2:$D$791,Analysis!$B$2:$B$791,">="&F7,Analysis!$B$2:$B$791,"<"&(F7+1)) -> 1360.7283 | J7: =Annual!H7 -> -0.13017276 | K7: =$O$16+$O$17*H7+$O$18*I7 -> -0.084561575 | N7: Years in fit | O7: =COUNT($G$2:$G$66) -> 65
A8: =Analysis!A8 -> 9/1958 | B8: =Analysis!E8 -> -0.03 | C8: =Analysis!F8 -> 0.16170345 | D8: 1362.04 | F8: 1965 | G8: =AVERAGEIFS(Analysis!$E$2:$E$823,Analysis!$B$2:$B$823,">="&F8,Analysis!$B$2:$B$823,"<"&(F8+1)) -> -0.10666667 | H8: =AVERAGEIFS(Analysis!$F$2:$F$823,Analysis!$B$2:$B$823,">="&F8,Analysis!$B$2:$B$823,"<"&(F8+1)) -> 0.19279249 | I8: =AVERAGEIFS($D$2:$D$791,Analysis!$B$2:$B$791,">="&F8,Analysis!$B$2:$B$791,"<"&(F8+1)) -> 1360.7725 | J8: =Annual!H8 -> -0.042843646 | K8: =$O$16+$O$17*H8+$O$18*I8 -> -0.076563742 | N8: TSI: mean (W/m²) | O8: =AVERAGE($I$2:$I$66) -> 1361.0745
A9: =Analysis!A9 -> 10/1958 | B9: =Analysis!E9 -> 0.04 | C9: =Analysis!F9 -> 0.15805999 | D9: 1361.99 | F9: 1966 | G9: =AVERAGEIFS(Analysis!$E$2:$E$823,Analysis!$B$2:$B$823,">="&F9,Analysis!$B$2:$B$823,"<"&(F9+1)) -> -0.0575 | H9: =AVERAGEIFS(Analysis!$F$2:$F$823,Analysis!$B$2:$B$823,">="&F9,Analysis!$B$2:$B$823,"<"&(F9+1)) -> 0.19877222 | I9: =AVERAGEIFS($D$2:$D$791,Analysis!$B$2:$B$791,">="&F9,Analysis!$B$2:$B$791,"<"&(F9+1)) -> 1361.0008 | J9: =Annual!H9 -> -0.010075723 | K9: =$O$16+$O$17*H9+$O$18*I9 -> -0.045248767 | N9: TSI: max minus min (W/m²) | O9: =MAX($I$2:$I$66)-MIN($I$2:$I$66) -> 1.3983333
A10: =Analysis!A10 -> 11/1958 | B10: =Analysis!E10 -> 0.02 | C10: =Analysis!F10 -> 0.16225608 | D10: 1362.07 | F10: 1967 | G10: =AVERAGEIFS(Analysis!$E$2:$E$823,Analysis!$B$2:$B$823,">="&F10,Analysis!$B$2:$B$823,"<"&(F10+1)) -> -0.024166667 | H10: =AVERAGEIFS(Analysis!$F$2:$F$823,Analysis!$B$2:$B$823,">="&F10,Analysis!$B$2:$B$823,"<"&(F10+1)) -> 0.20241456 | I10: =AVERAGEIFS($D$2:$D$791,Analysis!$B$2:$B$791,">="&F10,Analysis!$B$2:$B$791,"<"&(F10+1)) -> 1361.225 | J10: =Annual!H10 -> 0.013268899 | K10: =$O$16+$O$17*H10+$O$18*I10 -> -0.020437758 | N10: TSI linear trend, W/m² per decade | O10: =SLOPE($I$2:$I$66,$F$2:$F$66)*10 -> -0.0069777098
A11: =Analysis!A11 -> 12/1958 | B11: =Analysis!E11 -> 0.01 | C11: =Analysis!F11 -> 0.16841281 | D11: 1361.54 | F11: 1968 | G11: =AVERAGEIFS(Analysis!$E$2:$E$823,Analysis!$B$2:$B$823,">="&F11,Analysis!$B$2:$B$823,"<"&(F11+1)) -> -0.0825 | H11: =AVERAGEIFS(Analysis!$F$2:$F$823,Analysis!$B$2:$B$823,">="&F11,Analysis!$B$2:$B$823,"<"&(F11+1)) -> 0.20630941 | I11: =AVERAGEIFS($D$2:$D$791,Analysis!$B$2:$B$791,">="&F11,Analysis!$B$2:$B$791,"<"&(F11+1)) -> 1361.3042 | J11: =Annual!H11 -> -0.055745643 | K11: =$O$16+$O$17*H11+$O$18*I11 -> -0.0047305884 | N11: R², anomaly vs TSI alone | O11: =RSQ($G$2:$G$66,$I$2:$I$66) -> 0.0015483771
